Workbook
Name Slicer_Representative: #N/A

Sheet Analysis
A2: Amount
A3: Row Labels | B3: Sum of Purchase Amount | E3: Calls | F3: Amount | G3: Call time | H3: Average Rating | I3: Happy Calls
A4: R01 | B4: 18415 | E4: 1000 | F4: 96623 | G4: 89850 | H4: 3.8854 | I4: 735
A5: R02 | B5: 20581
A6: R03 | B6: 20872
A7: R04 | B7: 16651
A8: R05 | B8: 20104
A11: Calls
A12: Row Labels | B12: Count of Call number
A13: R01 | B13: 189
A14: R02 | B14: 218
A15: R03 | B15: 207
A16: R04 | B16: 186
A17: R05 | B17: 200
A21: Call Trend | D21: Call trend(weekday)
A22: Row Labels | B22: Count of Call number | D22: Row Labels | E22: Count of Call number
A23: Jan | B23: 79 | D23: Monday | E23: 133
A24: Feb | B24: 66 | D24: Tuesday | E24: 138
A25: Mar | B25: 155 | D25: Wednesday | E25: 153
A26: Apr | B26: 136 | D26: Thursday | E26: 128
A27: May | B27: 83 | D27: Friday | E27: 141
A28: Jun | B28: 67 | D28: Saturday | E28: 161
A29: Jul | B29: 64 | D29: Sunday | E29: 146
A30: Aug | B30: 50
A31: Sep | B31: 76
A32: Oct | B32: 114
A33: Nov | B33: 57
A34: Dec | B34: 53
A37: Row Labels | B37: Sum of Rating rounded
A38: 1 | B38: 8
A39: 2 | B39: 118
A40: 3 | B40: 591
A41: 4 | B41: 1712
A42: 5 | B42: 1535
A46: Sum of Purchase Amount | C46: Representative
A47: City | B47: Customer ID | C47: R01 | D47: R02 | E47: R03 | F47: R04 | G47: R05 | H47: Grand Total
A48: Cincinnati | B48: C0003 | C48: 891 | D48: 1332 | E48: 1282 | F48: 739 | G48: 560 | H48: 4804
B49: C0004 | C49: 1991 | D49: 1886 | E49: 1206 | F49: 884 | G49: 1722 | H49: 7689
B50: C0011 | C50: 1163 | D50: 1180 | E50: 1616 | F50: 1043 | G50: 1747 | H50: 6749
B51: C0012 | C51: 1438 | D51: 1616 | E51: 866 | F51: 829 | G51: 2070 | H51: 6819
...

Sheet Dashboard
B2: CALL CENTRE REPORT - 2023
N20: CustomerID | O20: R01 | P20: R02 | Q20: R03 | R20: R04 | S20: R05 | T20: Total
M21: =Analysis!A48 -> Cincinnati | N21: =Analysis!B48 -> C0003 | O21: =Analysis!C48 -> 891 | P21: =Analysis!D48 -> 1332 | Q21: =Analysis!E48 -> 1282 | R21: =Analysis!F48 -> 739 | S21: =Analysis!G48 -> 560 | T21: =Analysis!H48 -> 4804
N22: =Analysis!B49 -> C0004 | O22: =Analysis!C49 -> 1991 | P22: =Analysis!D49 -> 1886 | Q22: =Analysis!E49 -> 1206 | R22: =Analysis!F49 -> 884 | S22: =Analysis!G49 -> 1722 | T22: =Analysis!H49 -> 7689
N23: =Analysis!B50 -> C0011 | O23: =Analysis!C50 -> 1163 | P23: =Analysis!D50 -> 1180 | Q23: =Analysis!E50 -> 1616 | R23: =Analysis!F50 -> 1043 | S23: =Analysis!G50 -> 1747 | T23: =Analysis!H50 -> 6749
N24: =Analysis!B51 -> C0012 | O24: =Analysis!C51 -> 1438 | P24: =Analysis!D51 -> 1616 | Q24: =Analysis!E51 -> 866 | R24: =Analysis!F51 -> 829 | S24: =Analysis!G51 -> 2070 | T24: =Analysis!H51 -> 6819
M26: =Analysis!A53 -> Cleveland | N26: =Analysis!B53 -> C0002 | O26: =Analysis!C53 -> 1233 | P26: =Analysis!D53 -> 223 | Q26: =Analysis!E53 -> 1680 | R26: =Analysis!F53 -> 990 | S26: =Analysis!G53 -> 1508 | T26: =Analysis!H53 -> 5634
N27: =Analysis!B54 -> C0007 | O27: =Analysis!C54 -> 1598 | P27: =Analysis!D54 -> 1907 | Q27: =Analysis!E54 -> 869 | R27: =Analysis!F54 -> 1426 | S27: =Analysis!G54 -> 1416 | T27: =Analysis!H54 -> 7216
N28: =Analysis!B55 -> C0008 | O28: =Analysis!C55 -> 900 | P28: =Analysis!D55 -> 1016 | Q28: =Analysis!E55 -> 960 | R28: =Analysis!F55 -> 940 | S28: =Analysis!G55 -> 1193 | T28: =Analysis!H55 -> 5009
N29: =Analysis!B56 -> C0010 | O29: =Analysis!C56 -> 900 | P29: =Analysis!D56 -> 1470 | Q29: =Analysis!E56 -> 1617 | R29: =Analysis!F56 -> 1314 | S29: =Analysis!G56 -> 941 | T29: =Analysis!H56 -> 6242
N30: =Analysis!B57 -> C0013 | O30: =Analysis!C57 -> 1255 | P30: =Analysis!D57 -> 516 | Q30: =Analysis!E57 -> 1874 | R30: =Analysis!F57 -> 1863 | S30: =Analysis!G57 -> 1722 | T30: =Analysis!H57 -> 7230
N31: =Analysis!B58 -> C0015 | O31: =Analysis!C58 -> 1138 | P31: =Analysis!D58 -> 1898 | Q31: =Analysis!E58 -> 1482 | R31: =Analysis!F58 -> 846 | S31: =Analysis!G58 -> 1154 | T31: =Analysis!H58 -> 6518
M33: =Analysis!A60 -> Columbus | N33: =Analysis!B60 -> C0001 | O33: =Analysis!C60 -> 1655 | P33: =Analysis!D60 -> 805 | Q33: =Analysis!E60 -> 2263 | R33: =Analysis!F60 -> 987 | S33: =Analysis!G60 -> 1075 | T33: =Analysis!H60 -> 6785
N34: =Analysis!B61 -> C0005 | O34: =Analysis!C61 -> 1104 | P34: =Analysis!D61 -> 2280 | Q34: =Analysis!E61 -> 1445 | R34: =Analysis!F61 -> 1722 | S34: =Analysis!G61 -> 1196 | T34: =Analysis!H61 -> 7747
N35: =Analysis!B62 -> C0006 | O35: =Analysis!C62 -> 372 | P35: =Analysis!D62 -> 1818 | Q35: =Analysis!E62 -> 1346 | R35: =Analysis!F62 -> 1156 | S35: =Analysis!G62 -> 1484 | T35: =Analysis!H62 -> 6176
N36: =Analysis!B63 -> C0009 | O36: =Analysis!C63 -> 1415 | P36: =Analysis!D63 -> 1271 | Q36: =Analysis!E63 -> 1214 | R36: =Analysis!F63 -> 1135 | S36: =Analysis!G63 -> 1566 | T36: =Analysis!H63 -> 6601
N37: =Analysis!B64 -> C0014 | O37: =Analysis!C64 -> 1362 | P37: =Analysis!D64 -> 1363 | Q37: =Analysis!E64 -> 1152 | R37: =Analysis!F64 -> 777 | S37: =Analysis!G64 -> 750 | T37: =Analysis!H64 -> 5404

Sheet Data
B1: Call Centre Data
B3: Call number | C3: Customer ID | D3: Duration | E3: Representative | F3: Date of Call | G3: Purchase Amount | H3: Satisfaction Rating | I3: FY | J3: Day of week | K3: Duration Bucket | L3: Rating rounded | M3: happy_calls | N3: Gender | O3: Age | P3: City | T3: Customer ID | U3: Gedner | V3: Age | W3: City
B4: Call_7271 | C4: C0003 | D4: 116 | E4: R05 | F4: 44927 | G4: 128 | H4: 4.9 | I4: =IF(MONTH(calls[[#This Row],[Date of Call]])<=6, YEAR(calls[[#This Row],[Date of Call]]), YEAR(calls[[#This Row],[Date of Call]])+1) -> 2023 | J4: =TEXT(calls[[#This Row],[Date of Call]],"DDDD") -> Sunday | K4: {=_xlfn.IFS(calls[[#This Row],[Duration]]<=10,"Under 10 mins", calls[[#This Row],[Duration]]<=30, "10 to 30 mins", calls[[#This Row],[Duration]]<=60, "30 to 60 mins", calls[[#This Row],[Duration]]<=120, "1 to 2 hours", TRUE, "More than 2 hours")} -> 1 to 2 hours | L4: =ROUND(calls[[#This Row],[Satisfaction Rating]],0) -> 5 | M4: =IF(calls[[#This Row],[Rating rounded]]>=4,"Happy") -> Happy | N4: =_xlfn.XLOOKUP(calls[[#This Row],[Customer ID]],customers[Customer ID],customers[Gedner]) -> Male | O4: =_xlfn.XLOOKUP(calls[[#This Row],[Customer ID]],customers[Customer ID],customers[Age]) -> 26 | P4: =_xlfn.XLOOKUP(calls[[#This Row],[Customer ID]],customers[Customer ID],customers[City]) -> Cincinnati | T4: C0001 | U4: Male | V4: 41 | W4: Columbus
B5: Call_7272 | C5: C0004 | D5: 119 | E5: R05 | F5: 44927 | G5: 135 | H5: 2.9 | I5: =IF(MONTH(calls[[#This Row],[Date of Call]])<=6, YEAR(calls[[#This Row],[Date of Call]]), YEAR(calls[[#This Row],[Date of Call]])+1) -> 2023 | J5: =TEXT(calls[[#This Row],[Date of Call]],"DDDD") -> Sunday | K5: {=_xlfn.IFS(calls[[#This Row],[Duration]]<=10,"Under 10 mins", calls[[#This Row],[Duration]]<=30, "10 to 30 mins", calls[[#This Row],[Duration]]<=60, "30 to 60 mins", calls[[#This Row],[Duration]]<=120, "1 to 2 hours", TRUE, "More than 2 hours")} -> 1 to 2 hours | L5: =ROUND(calls[[#This Row],[Satisfaction Rating]],0) -> 3 | M5: =IF(calls[[#This Row],[Rating rounded]]>=4,"Happy") -> FALSE | N5: =_xlfn.XLOOKUP(calls[[#This Row],[Customer ID]],customers[Customer ID],customers[Gedner]) -> Male | O5: =_xlfn.XLOOKUP(calls[[#This Row],[Customer ID]],customers[Customer ID],customers[Age]) -> 36 | P5: =_xlfn.XLOOKUP(calls[[#This Row],[Customer ID]],customers[Customer ID],customers[City]) -> Cincinnati | T5: C0002 | U5: Male | V5: 31 | W5: Cleveland
B6: Call_7273 | C6: C0005 | D6: 68 | E6: R02 | F6: 44927 | G6: 66 | H6: 4.7 | I6: =IF(MONTH(calls[[#This Row],[Date of Call]])<=6, YEAR(calls[[#This Row],[Date of Call]]), YEAR(calls[[#This Row],[Date of Call]])+1) -> 2023 | J6: =TEXT(calls[[#This Row],[Date of Call]],"DDDD") -> Sunday | K6: {=_xlfn.IFS(calls[[#This Row],[Duration]]<=10,"Under 10 mins", calls[[#This Row],[Duration]]<=30, "10 to 30 mins", calls[[#This Row],[Duration]]<=60, "30 to 60 mins", calls[[#This Row],[Duration]]<=120, "1 to 2 hours", TRUE, "More than 2 hours")} -> 1 to 2 hours | L6: =ROUND(calls[[#This Row],[Satisfaction Rating]],0) -> 5 | M6: =IF(calls[[#This Row],[Rating rounded]]>=4,"Happy") -> Happy | N6: =_xlfn.XLOOKUP(calls[[#This Row],[Customer ID]],customers[Customer ID],customers[Gedner]) -> Male | O6: =_xlfn.XLOOKUP(calls[[#This Row],[Customer ID]],customers[Customer ID],customers[Age]) -> 37 | P6: =_xlfn.XLOOKUP(calls[[#This Row],[Customer ID]],customers[Customer ID],customers[City]) -> Columbus | R6: =COUNTIF(calls[happy_calls],"Happy") -> 735 | T6: C0003 | U6: Male | V6: 26 | W6: Cincinnati
B7: Call_7274 | C7: C0014 | D7: 119 | E7: R02 | F7: 44927 | G7: 22 | H7: 2.9 | I7: =IF(MONTH(calls[[#This Row],[Date of Call]])<=6, YEAR(calls[[#This Row],[Date of Call]]), YEAR(calls[[#This Row],[Date of Call]])+1) -> 2023 | J7: =TEXT(calls[[#This Row],[Date of Call]],"DDDD") -> Sunday | K7: {=_xlfn.IFS(calls[[#This Row],[Duration]]<=10,"Under 10 mins", calls[[#This Row],[Duration]]<=30, "10 to 30 mins", calls[[#This Row],[Duration]]<=60, "30 to 60 mins", calls[[#This Row],[Duration]]<=120, "1 to 2 hours", TRUE, "More than 2 hours")} -> 1 to 2 hours | L7: =ROUND(calls[[#This Row],[Satisfaction Rating]],0) -> 3 | M7: =IF(calls[[#This Row],[Rating rounded]]>=4,"Happy") -> FALSE | N7: =_xlfn.XLOOKUP(calls[[#This Row],[Customer ID]],customers[Customer ID],customers[Gedner]) -> Female | O7: =_xlfn.XLOOKUP(calls[[#This Row],[Customer ID]],customers[Customer ID],customers[Age]) -> 38 | P7: =_xlfn.XLOOKUP(calls[[#This Row],[Customer ID]],customers[Customer ID],customers[City]) -> Columbus | T7: C0004 | U7: Male | V7: 36 | W7: Cincinnati
B8: Call_7275 | C8: C0011 | D8: 128 | E8: R01 | F8: 44928 | G8: 31 | H8: 2.8 | I8: =IF(MONTH(calls[[#This Row],[Date of Call]])<=6, YEAR(calls[[#This Row],[Date of Call]]), YEAR(calls[[#This Row],[Date of Call]])+1) -> 2023 | J8: =TEXT(calls[[#This Row],[Date of Call]],"DDDD") -> Monday | K8: {=_xlfn.IFS(calls[[#This Row],[Duration]]<=10,"Under 10 mins", calls[[#This Row],[Duration]]<=30, "10 to 30 mins", calls[[#This Row],[Duration]]<=60, "30 to 60 mins", calls[[#This Row],[Duration]]<=120, "1 to 2 hours", TRUE, "More than 2 hours")} -> More than 2 hours | L8: =ROUND(calls[[#This Row],[Satisfaction Rating]],0) -> 3 | M8: =IF(calls[[#This Row],[Rating rounded]]>=4,"Happy") -> FALSE | N8: =_xlfn.XLOOKUP(calls[[#This Row],[Customer ID]],customers[Customer ID],customers[Gedner]) -> Female | O8: =_xlfn.XLOOKUP(calls[[#This Row],[Customer ID]],customers[Customer ID],customers[Age]) -> 30 | P8: =_xlfn.XLOOKUP(calls[[#This Row],[Customer ID]],customers[Customer ID],customers[City]) -> Cincinnati | T8: C0005 | U8: Male | V8: 37 | W8: Columbus
B9: Call_7276 | C9: C0011 | D9: 49 | E9: R02 | F9: 44929 | G9: 135 | H9: 4.8 | I9: =IF(MONTH(calls[[#This Row],[Date of Call]])<=6, YEAR(calls[[#This Row],[Date of Call]]), YEAR(calls[[#This Row],[Date of Call]])+1) -> 2023 | J9: =TEXT(calls[[#This Row],[Date of Call]],"DDDD") -> Tuesday | K9: {=_xlfn.IFS(calls[[#This Row],[Duration]]<=10,"Under 10 mins", calls[[#This Row],[Duration]]<=30, "10 to 30 mins", calls[[#This Row],[Duration]]<=60, "30 to 60 mins", calls[[#This Row],[Duration]]<=120, "1 to 2 hours", TRUE, "More than 2 hours")} -> 30 to 60 mins | L9: =ROUND(calls[[#This Row],[Satisfaction Rating]],0) -> 5 | M9: =IF(calls[[#This Row],[Rating rounded]]>=4,"Happy") -> Happy | N9: =_xlfn.XLOOKUP(calls[[#This Row],[Customer ID]],customers[Customer ID],customers[Gedner]) -> Female | O9: =_xlfn.XLOOKUP(calls[[#This Row],[Customer ID]],customers[Customer ID],customers[Age]) -> 30 | P9: =_xlfn.XLOOKUP(calls[[#This Row],[Customer ID]],customers[Customer ID],customers[City]) -> Cincinnati | T9: C0006 | U9: Male | V9: 23 | W9: Columbus
B10: Call_7277 | C10: C0007 | D10: 84 | E10: R05 | F10: 44929 | G10: 60 | H10: 4.7 | I10: =IF(MONTH(calls[[#This Row],[Date of Call]])<=6, YEAR(calls[[#This Row],[Date of Call]]), YEAR(calls[[#This Row],[Date of Call]])+1) -> 2023 | J10: =TEXT(calls[[#This Row],[Date of Call]],"DDDD") -> Tuesday | K10: {=_xlfn.IFS(calls[[#This Row],[Duration]]<=10,"Under 10 mins", calls[[#This Row],[Duration]]<=30, "10 to 30 mins", calls[[#This Row],[Duration]]<=60, "30 to 60 mins", calls[[#This Row],[Duration]]<=120, "1 to 2 hours", TRUE, "More than 2 hours")} -> 1 to 2 hours | L10: =ROUND(calls[[#This Row],[Satisfaction Rating]],0) -> 5 | M10: =IF(calls[[#This Row],[Rating rounded]]>=4,"Happy") -> Happy | N10: =_xlfn.XLOOKUP(calls[[#This Row],[Customer ID]],customers[Customer ID],customers[Gedner]) -> Female | O10: =_xlfn.XLOOKUP(calls[[#This Row],[Customer ID]],customers[Customer ID],customers[Age]) -> 22 | P10: =_xlfn.XLOOKUP(calls[[#This Row],[Customer ID]],customers[Customer ID],customers[City]) -> Cleveland | T10: C0007 | U10: Female | V10: 22 | W10: Cleveland
B11: Call_7278 | C11: C0003 | D11: 103 | E11: R04 | F11: 44929 | G11: 148 | H11: 4.4 | I11: =IF(MONTH(calls[[#This Row],[Date of Call]])<=6, YEAR(calls[[#This Row],[Date of Call]]), YEAR(calls[[#This Row],[Date of Call]])+1) -> 2023 | J11: =TEXT(calls[[#This Row],[Date of Call]],"DDDD") -> Tuesday | K11: {=_xlfn.IFS(calls[[#This Row],[Duration]]<=10,"Under 10 mins", calls[[#This Row],[Duration]]<=30, "10 to 30 mins", calls[[#This Row],[Duration]]<=60, "30 to 60 mins", calls[[#This Row],[Duration]]<=120, "1 to 2 hours", TRUE, "More than 2 hours")} -> 1 to 2 hours | L11: =ROUND(calls[[#This Row],[Satisfaction Rating]],0) -> 4 | M11: =IF(calls[[#This Row],[Rating rounded]]>=4,"Happy") -> Happy | N11: =_xlfn.XLOOKUP(calls[[#This Row],[Customer ID]],customers[Customer ID],customers[Gedner]) -> Male | O11: =_xlfn.XLOOKUP(calls[[#This Row],[Customer ID]],customers[Customer ID],customers[Age]) -> 26 | P11: =_xlfn.XLOOKUP(calls[[#This Row],[Customer ID]],customers[Customer ID],customers[City]) -> Cincinnati | T11: C0008 | U11: Female | V11: 42 | W11: Cleveland
B12: Call_7279 | C12: C0005 | D12: 31 | E12: R02 | F12: 44929 | G12: 135 | H12: 3.6 | I12: =IF(MONTH(calls[[#This Row],[Date of Call]])<=6, YEAR(calls[[#This Row],[Date of Call]]), YEAR(calls[[#This Row],[Date of Call]])+1) -> 2023 | J12: =TEXT(calls[[#This Row],[Date of Call]],"DDDD") -> Tuesday | K12: {=_xlfn.IFS(calls[[#This Row],[Duration]]<=10,"Under 10 mins", calls[[#This Row],[Duration]]<=30, "10 to 30 mins", calls[[#This Row],[Duration]]<=60, "30 to 60 mins", calls[[#This Row],[Duration]]<=120, "1 to 2 hours", TRUE, "More than 2 hours")} -> 30 to 60 mins | L12: =ROUND(calls[[#This Row],[Satisfaction Rating]],0) -> 4 | M12: =IF(calls[[#This Row],[Rating rounded]]>=4,"Happy") -> Happy | N12: =_xlfn.XLOOKUP(calls[[#This Row],[Customer ID]],customers[Customer ID],customers[Gedner]) -> Male | O12: =_xlfn.XLOOKUP(calls[[#This Row],[Customer ID]],customers[Customer ID],customers[Age]) -> 37 | P12: =_xlfn.XLOOKUP(calls[[#This Row],[Customer ID]],customers[Customer ID],customers[City]) -> Columbus | T12: C0009 | U12: Female | V12: 25 | W12: Columbus
B13: Call_7280 | C13: C0010 | D13: 44 | E13: R03 | F13: 44929 | G13: 105 | H13: 2.9 | I13: =IF(MONTH(calls[[#This Row],[Date of Call]])<=6, YEAR(calls[[#This Row],[Date of Call]]), YEAR(calls[[#This Row],[Date of Call]])+1) -> 2023 | J13: =TEXT(calls[[#This Row],[Date of Call]],"DDDD") -> Tuesday | K13: {=_xlfn.IFS(calls[[#This Row],[Duration]]<=10,"Under 10 mins", calls[[#This Row],[Duration]]<=30, "10 to 30 mins", calls[[#This Row],[Duration]]<=60, "30 to 60 mins", calls[[#This Row],[Duration]]<=120, "1 to 2 hours", TRUE, "More than 2 hours")} -> 30 to 60 mins | L13: =ROUND(calls[[#This Row],[Satisfaction Rating]],0) -> 3 | M13: =IF(calls[[#This Row],[Rating rounded]]>=4,"Happy") -> FALSE | N13: =_xlfn.XLOOKUP(calls[[#This Row],[Customer ID]],customers[Customer ID],customers[Gedner]) -> Female | O13: =_xlfn.XLOOKUP(calls[[#This Row],[Customer ID]],customers[Customer ID],customers[Age]) -> 30 | P13: =_xlfn.XLOOKUP(calls[[#This Row],[Customer ID]],customers[Customer ID],customers[City]) -> Cleveland | T13: C0010 | U13: Female | V13: 30 | W13: Cleveland
B14: Call_7281 | C14: C0011 | D14: 102 | E14: R02 | F14: 44929 | G14: 69 | H14: 4.9 | I14: =IF(MONTH(calls[[#This Row],[Date of Call]])<=6, YEAR(calls[[#This Row],[Date of Call]]), YEAR(calls[[#This Row],[Date of Call]])+1) -> 2023 | J14: =TEXT(calls[[#This Row],[Date of Call]],"DDDD") -> Tuesday | K14: {=_xlfn.IFS(calls[[#This Row],[Duration]]<=10,"Under 10 mins", calls[[#This Row],[Duration]]<=30, "10 to 30 mins", calls[[#This Row],[Duration]]<=60, "30 to 60 mins", calls[[#This Row],[Duration]]<=120, "1 to 2 hours", TRUE, "More than 2 hours")} -> 1 to 2 hours | L14: =ROUND(calls[[#This Row],[Satisfaction Rating]],0) -> 5 | M14: =IF(calls[[#This Row],[Rating rounded]]>=4,"Happy") -> Happy | N14: =_xlfn.XLOOKUP(calls[[#This Row],[Customer ID]],customers[Customer ID],customers[Gedner]) -> Female | O14: =_xlfn.XLOOKUP(calls[[#This Row],[Customer ID]],customers[Customer ID],customers[Age]) -> 30 | P14: =_xlfn.XLOOKUP(calls[[#This Row],[Customer ID]],customers[Customer ID],customers[City]) -> Cincinnati | T14: C0011 | U14: Female | V14: 30 | W14: Cincinnati
B15: Call_7282 | C15: C0013 | D15: 135 | E15: R05 | F15: 44929 | G15: 46 | H15: 3.4 | I15: =IF(MONTH(calls[[#This Row],[Date of Call]])<=6, YEAR(calls[[#This Row],[Date of Call]]), YEAR(calls[[#This Row],[Date of Call]])+1) -> 2023 | J15: =TEXT(calls[[#This Row],[Date of Call]],"DDDD") -> Tuesday | K15: {=_xlfn.IFS(calls[[#This Row],[Duration]]<=10,"Under 10 mins", calls[[#This Row],[Duration]]<=30, "10 to 30 mins", calls[[#This Row],[Duration]]<=60, "30 to 60 mins", calls[[#This Row],[Duration]]<=120, "1 to 2 hours", TRUE, "More than 2 hours")} -> More than 2 hours | L15: =ROUND(calls[[#This Row],[Satisfaction Rating]],0) -> 3 | M15: =IF(calls[[#This Row],[Rating rounded]]>=4,"Happy") -> FALSE | N15: =_xlfn.XLOOKUP(calls[[#This Row],[Customer ID]],customers[Customer ID],customers[Gedner]) -> Female | O15: =_xlfn.XLOOKUP(calls[[#This Row],[Customer ID]],customers[Customer ID],customers[Age]) -> 37 | P15: =_xlfn.XLOOKUP(calls[[#This Row],[Customer ID]],customers[Customer ID],customers[City]) -> Cleveland | T15: C0012 | U15: Female | V15: 28 | W15: Cincinnati
B16: Call_7283 | C16: C0002 | D16: 98 | E16: R02 | F16: 44930 | G16: 108 | H16: 3.5 | I16: =IF(MONTH(calls[[#This Row],[Date of Call]])<=6, YEAR(calls[[#This Row],[Date of Call]]), YEAR(calls[[#This Row],[Date of Call]])+1) -> 2023 | J16: =TEXT(calls[[#This Row],[Date of Call]],"DDDD") -> Wednesday | K16: {=_xlfn.IFS(calls[[#This Row],[Duration]]<=10,"Under 10 mins", calls[[#This Row],[Duration]]<=30, "10 to 30 mins", calls[[#This Row],[Duration]]<=60, "30 to 60 mins", calls[[#This Row],[Duration]]<=120, "1 to 2 hours", TRUE, "More than 2 hours")} -> 1 to 2 hours | L16: =ROUND(calls[[#This Row],[Satisfaction Rating]],0) -> 4 | M16: =IF(calls[[#This Row],[Rating rounded]]>=4,"Happy") -> Happy | N16: =_xlfn.XLOOKUP(calls[[#This Row],[Customer ID]],customers[Customer ID],customers[Gedner]) -> Male | O16: =_xlfn.XLOOKUP(calls[[#This Row],[Customer ID]],customers[Customer ID],customers[Age]) -> 31 | P16: =_xlfn.XLOOKUP(calls[[#This Row],[Customer ID]],customers[Customer ID],customers[City]) -> Cleveland | T16: C0013 | U16: Female | V16: 37 | W16: Cleveland
B17: Call_7284 | C17: C0010 | D17: 139 | E17: R02 | F17: 44930 | G17: 96 | H17: 4 | I17: =IF(MONTH(calls[[#This Row],[Date of Call]])<=6, YEAR(calls[[#This Row],[Date of Call]]), YEAR(calls[[#This Row],[Date of Call]])+1) -> 2023 | J17: =TEXT(calls[[#This Row],[Date of Call]],"DDDD") -> Wednesday | K17: {=_xlfn.IFS(calls[[#This Row],[Duration]]<=10,"Under 10 mins", calls[[#This Row],[Duration]]<=30, "10 to 30 mins", calls[[#This Row],[Duration]]<=60, "30 to 60 mins", calls[[#This Row],[Duration]]<=120, "1 to 2 hours", TRUE, "More than 2 hours")} -> More than 2 hours | L17: =ROUND(calls[[#This Row],[Satisfaction Rating]],0) -> 4 | M17: =IF(calls[[#This Row],[Rating rounded]]>=4,"Happy") -> Happy | N17: =_xlfn.XLOOKUP(calls[[#This Row],[Customer ID]],customers[Customer ID],customers[Gedner]) -> Female | O17: =_xlfn.XLOOKUP(calls[[#This Row],[Customer ID]],customers[Customer ID],customers[Age]) -> 30 | P17: =_xlfn.XLOOKUP(calls[[#This Row],[Customer ID]],customers[Customer ID],customers[City]) -> Cleveland | T17: C0014 | U17: Female | V17: 38 | W17: Columbus
B18: Call_7285 | C18: C0013 | D18: 48 | E18: R01 | F18: 44930 | G18: 68 | H18: 4.9 | I18: =IF(MONTH(calls[[#This Row],[Date of Call]])<=6, YEAR(calls[[#This Row],[Date of Call]]), YEAR(calls[[#This Row],[Date of Call]])+1) -> 2023 | J18: =TEXT(calls[[#This Row],[Date of Call]],"DDDD") -> Wednesday | K18: {=_xlfn.IFS(calls[[#This Row],[Duration]]<=10,"Under 10 mins", calls[[#This Row],[Duration]]<=30, "10 to 30 mins", calls[[#This Row],[Duration]]<=60, "30 to 60 mins", calls[[#This Row],[Duration]]<=120, "1 to 2 hours", TRUE, "More than 2 hours")} -> 30 to 60 mins | L18: =ROUND(calls[[#This Row],[Satisfaction Rating]],0) -> 5 | M18: =IF(calls[[#This Row],[Rating rounded]]>=4,"Happy") -> Happy | N18: =_xlfn.XLOOKUP(calls[[#This Row],[Customer ID]],customers[Customer ID],customers[Gedner]) -> Female | O18: =_xlfn.XLOOKUP(calls[[#This Row],[Customer ID]],customers[Customer ID],customers[Age]) -> 37 | P18: =_xlfn.XLOOKUP(calls[[#This Row],[Customer ID]],customers[Customer ID],customers[City]) -> Cleveland | T18: C0015 | U18: Female | V18: 43 | W18: Cleveland
B19: Call_7286 | C19: C0010 | D19: 176 | E19: R05 | F19: 44931 | G19: 24 | H19: 4.8 | I19: =IF(MONTH(calls[[#This Row],[Date of Call]])<=6, YEAR(calls[[#This Row],[Date of Call]]), YEAR(calls[[#This Row],[Date of Call]])+1) -> 2023 | J19: =TEXT(calls[[#This Row],[Date of Call]],"DDDD") -> Thursday | K19: {=_xlfn.IFS(calls[[#This Row],[Duration]]<=10,"Under 10 mins", calls[[#This Row],[Duration]]<=30, "10 to 30 mins", calls[[#This Row],[Duration]]<=60, "30 to 60 mins", calls[[#This Row],[Duration]]<=120, "1 to 2 hours", TRUE, "More than 2 hours")} -> More than 2 hours | L19: =ROUND(calls[[#This Row],[Satisfaction Rating]],0) -> 5 | M19: =IF(calls[[#This Row],[Rating rounded]]>=4,"Happy") -> Happy | N19: =_xlfn.XLOOKUP(calls[[#This Row],[Customer ID]],customers[Customer ID],customers[Gedner]) -> Female | O19: =_xlfn.XLOOKUP(calls[[#This Row],[Customer ID]],customers[Customer ID],customers[Age]) -> 30 | P19: =_xlfn.XLOOKUP(calls[[#This Row],[Customer ID]],customers[Customer ID],customers[City]) -> Cleveland
B20: Call_7287 | C20: C0010 | D20: 99 | E20: R01 | F20: 44931 | G20: 195 | H20: 3.9 | I20: =IF(MONTH(calls[[#This Row],[Date of Call]])<=6, YEAR(calls[[#This Row],[Date of Call]]), YEAR(calls[[#This Row],[Date of Call]])+1) -> 2023 | J20: =TEXT(calls[[#This Row],[Date of Call]],"DDDD") -> Thursday | K20: {=_xlfn.IFS(calls[[#This Row],[Duration]]<=10,"Under 10 mins", calls[[#This Row],[Duration]]<=30, "10 to 30 mins", calls[[#This Row],[Duration]]<=60, "30 to 60 mins", calls[[#This Row],[Duration]]<=120, "1 to 2 hours", TRUE, "More than 2 hours")} -> 1 to 2 hours | L20: =ROUND(calls[[#This Row],[Satisfaction Rating]],0) -> 4 | M20: =IF(calls[[#This Row],[Rating rounded]]>=4,"Happy") -> Happy | N20: =_xlfn.XLOOKUP(calls[[#This Row],[Customer ID]],customers[Customer ID],customers[Gedner]) -> Female | O20: =_xlfn.XLOOKUP(calls[[#This Row],[Customer ID]],customers[Customer ID],customers[Age]) -> 30 | P20: =_xlfn.XLOOKUP(calls[[#This Row],[Customer ID]],customers[Customer ID],customers[City]) -> Cleveland
B21: Call_7288 | C21: C0009 | D21: 28 | E21: R03 | F21: 44931 | G21: 28 | H21: 3.8 | I21: =IF(MONTH(calls[[#This Row],[Date of Call]])<=6, YEAR(calls[[#This Row],[Date of Call]]), YEAR(calls[[#This Row],[Date of Call]])+1) -> 2023 | J21: =TEXT(calls[[#This Row],[Date of Call]],"DDDD") -> Thursday | K21: {=_xlfn.IFS(calls[[#This Row],[Duration]]<=10,"Under 10 mins", calls[[#This Row],[Duration]]<=30, "10 to 30 mins", calls[[#This Row],[Duration]]<=60, "30 to 60 mins", calls[[#This Row],[Duration]]<=120, "1 to 2 hours", TRUE, "More than 2 hours")} -> 10 to 30 mins | L21: =ROUND(calls[[#This Row],[Satisfaction Rating]],0) -> 4 | M21: =IF(calls[[#This Row],[Rating rounded]]>=4,"Happy") -> Happy | N21: =_xlfn.XLOOKUP(calls[[#This Row],[Customer ID]],customers[Customer ID],customers[Gedner]) -> Female | O21: =_xlfn.XLOOKUP(calls[[#This Row],[Customer ID]],customers[Customer ID],customers[Age]) -> 25 | P21: =_xlfn.XLOOKUP(calls[[#This Row],[Customer ID]],customers[Customer ID],customers[City]) -> Columbus
B22: Call_7289 | C22: C0007 | D22: 54 | E22: R02 | F22: 44931 | G22: 170 | H22: 4.3 | I22: =IF(MONTH(calls[[#This Row],[Date of Call]])<=6, YEAR(calls[[#This Row],[Date of Call]]), YEAR(calls[[#This Row],[Date of Call]])+1) -> 2023 | J22: =TEXT(calls[[#This Row],[Date of Call]],"DDDD") -> Thursday | K22: {=_xlfn.IFS(calls[[#This Row],[Duration]]<=10,"Under 10 mins", calls[[#This Row],[Duration]]<=30, "10 to 30 mins", calls[[#This Row],[Duration]]<=60, "30 to 60 mins", calls[[#This Row],[Duration]]<=120, "1 to 2 hours", TRUE, "More than 2 hours")} -> 30 to 60 mins | L22: =ROUND(calls[[#This Row],[Satisfaction Rating]],0) -> 4 | M22: =IF(calls[[#This Row],[Rating rounded]]>=4,"Happy") -> Happy | N22: =_xlfn.XLOOKUP(calls[[#This Row],[Customer ID]],customers[Customer ID],customers[Gedner]) -> Female | O22: =_xlfn.XLOOKUP(calls[[#This Row],[Customer ID]],customers[Customer ID],customers[Age]) -> 22 | P22: =_xlfn.XLOOKUP(calls[[#This Row],[Customer ID]],customers[Customer ID],customers[City]) -> Cleveland
B23: Call_7290 | C23: C0006 | D23: 48 | E23: R05 | F23: 44932 | G23: 30 | H23: 4.4 | I23: =IF(MONTH(calls[[#This Row],[Date of Call]])<=6, YEAR(calls[[#This Row],[Date of Call]]), YEAR(calls[[#This Row],[Date of Call]])+1) -> 2023 | J23: =TEXT(calls[[#This Row],[Date of Call]],"DDDD") -> Friday | K23: {=_xlfn.IFS(calls[[#This Row],[Duration]]<=10,"Under 10 mins", calls[[#This Row],[Duration]]<=30, "10 to 30 mins", calls[[#This Row],[Duration]]<=60, "30 to 60 mins", calls[[#This Row],[Duration]]<=120, "1 to 2 hours", TRUE, "More than 2 hours")} -> 30 to 60 mins | L23: =ROUND(calls[[#This Row],[Satisfaction Rating]],0) -> 4 | M23: =IF(calls[[#This Row],[Rating rounded]]>=4,"Happy") -> Happy | N23: =_xlfn.XLOOKUP(calls[[#This Row],[Customer ID]],customers[Customer ID],customers[Gedner]) -> Male | O23: =_xlfn.XLOOKUP(calls[[#This Row],[Customer ID]],customers[Customer ID],customers[Age]) -> 23 | P23: =_xlfn.XLOOKUP(calls[[#This Row],[Customer ID]],customers[Customer ID],customers[City]) -> Columbus
B24: Call_7291 | C24: C0004 | D24: 128 | E24: R05 | F24: 44932 | G24: 72 | H24: 5 | I24: =IF(MONTH(calls[[#This Row],[Date of Call]])<=6, YEAR(calls[[#This Row],[Date of Call]]), YEAR(calls[[#This Row],[Date of Call]])+1) -> 2023 | J24: =TEXT(calls[[#This Row],[Date of Call]],"DDDD") -> Friday | K24: {=_xlfn.IFS(calls[[#This Row],[Duration]]<=10,"Under 10 mins", calls[[#This Row],[Duration]]<=30, "10 to 30 mins", calls[[#This Row],[Duration]]<=60, "30 to 60 mins", calls[[#This Row],[Duration]]<=120, "1 to 2 hours", TRUE, "More than 2 hours")} -> More than 2 hours | L24: =ROUND(calls[[#This Row],[Satisfaction Rating]],0) -> 5 | M24: =IF(calls[[#This Row],[Rating rounded]]>=4,"Happy") -> Happy | N24: =_xlfn.XLOOKUP(calls[[#This Row],[Customer ID]],customers[Customer ID],customers[Gedner]) -> Male | O24: =_xlfn.XLOOKUP(calls[[#This Row],[Customer ID]],customers[Customer ID],customers[Age]) -> 36 | P24: =_xlfn.XLOOKUP(calls[[#This Row],[Customer ID]],customers[Customer ID],customers[City]) -> Cincinnati
B25: Call_7292 | C25: C0004 | D25: 38 | E25: R04 | F25: 44933 | G25: 92 | H25: 4.9 | I25: =IF(MONTH(calls[[#This Row],[Date of Call]])<=6, YEAR(calls[[#This Row],[Date of Call]]), YEAR(calls[[#This Row],[Date of Call]])+1) -> 2023 | J25: =TEXT(calls[[#This Row],[Date of Call]],"DDDD") -> Saturday | K25: {=_xlfn.IFS(calls[[#This Row],[Duration]]<=10,"Under 10 mins", calls[[#This Row],[Duration]]<=30, "10 to 30 mins", calls[[#This Row],[Duration]]<=60, "30 to 60 mins", calls[[#This Row],[Duration]]<=120, "1 to 2 hours", TRUE, "More than 2 hours")} -> 30 to 60 mins | L25: =ROUND(calls[[#This Row],[Satisfaction Rating]],0) -> 5 | M25: =IF(calls[[#This Row],[Rating rounded]]>=4,"Happy") -> Happy | N25: =_xlfn.XLOOKUP(calls[[#This Row],[Customer ID]],customers[Customer ID],customers[Gedner]) -> Male | O25: =_xlfn.XLOOKUP(calls[[#This Row],[Customer ID]],customers[Customer ID],customers[Age]) -> 36 | P25: =_xlfn.XLOOKUP(calls[[#This Row],[Customer ID]],customers[Customer ID],customers[City]) -> Cincinnati
B26: Call_7293 | C26: C0003 | D26: 67 | E26: R04 | F26: 44934 | G26: 165 | H26: 4.5 | I26: =IF(MONTH(calls[[#This Row],[Date of Call]])<=6, YEAR(calls[[#This Row],[Date of Call]]), YEAR(calls[[#This Row],[Date of Call]])+1) -> 2023 | J26: =TEXT(calls[[#This Row],[Date of Call]],"DDDD") -> Sunday | K26: {=_xlfn.IFS(calls[[#This Row],[Duration]]<=10,"Under 10 mins", calls[[#This Row],[Duration]]<=30, "10 to 30 mins", calls[[#This Row],[Duration]]<=60, "30 to 60 mins", calls[[#This Row],[Duration]]<=120, "1 to 2 hours", TRUE, "More than 2 hours")} -> 1 to 2 hours | L26: =ROUND(calls[[#This Row],[Satisfaction Rating]],0) -> 5 | M26: =IF(calls[[#This Row],[Rating rounded]]>=4,"Happy") -> Happy | N26: =_xlfn.XLOOKUP(calls[[#This Row],[Customer ID]],customers[Customer ID],customers[Gedner]) -> Male | O26: =_xlfn.XLOOKUP(calls[[#This Row],[Customer ID]],customers[Customer ID],customers[Age]) -> 26 | P26: =_xlfn.XLOOKUP(calls[[#This Row],[Customer ID]],customers[Customer ID],customers[City]) -> Cincinnati
B27: Call_7294 | C27: C0015 | D27: 58 | E27: R02 | F27: 44934 | G27: 140 | H27: 2.1 | I27: =IF(MONTH(calls[[#This Row],[Date of Call]])<=6, YEAR(calls[[#This Row],[Date of Call]]), YEAR(calls[[#This Row],[Date of Call]])+1) -> 2023 | J27: =TEXT(calls[[#This Row],[Date of Call]],"DDDD") -> Sunday | K27: {=_xlfn.IFS(calls[[#This Row],[Duration]]<=10,"Under 10 mins", calls[[#This Row],[Duration]]<=30, "10 to 30 mins", calls[[#This Row],[Duration]]<=60, "30 to 60 mins", calls[[#This Row],[Duration]]<=120, "1 to 2 hours", TRUE, "More than 2 hours")} -> 30 to 60 mins | L27: =ROUND(calls[[#This Row],[Satisfaction Rating]],0) -> 2 | M27: =IF(calls[[#This Row],[Rating rounded]]>=4,"Happy") -> FALSE | N27: =_xlfn.XLOOKUP(calls[[#This Row],[Customer ID]],customers[Customer ID],customers[Gedner]) -> Female | O27: =_xlfn.XLOOKUP(calls[[#This Row],[Customer ID]],customers[Customer ID],customers[Age]) -> 43 | P27: =_xlfn.XLOOKUP(calls[[#This Row],[Customer ID]],customers[Customer ID],customers[City]) -> Cleveland
B28: Call_7295 | C28: C0010 | D28: 54 | E28: R01 | F28: 44934 | G28: 111 | H28: 3.3 | I28: =IF(MONTH(calls[[#This Row],[Date of Call]])<=6, YEAR(calls[[#This Row],[Date of Call]]), YEAR(calls[[#This Row],[Date of Call]])+1) -> 2023 | J28: =TEXT(calls[[#This Row],[Date of Call]],"DDDD") -> Sunday | K28: {=_xlfn.IFS(calls[[#This Row],[Duration]]<=10,"Under 10 mins", calls[[#This Row],[Duration]]<=30, "10 to 30 mins", calls[[#This Row],[Duration]]<=60, "30 to 60 mins", calls[[#This Row],[Duration]]<=120, "1 to 2 hours", TRUE, "More than 2 hours")} -> 30 to 60 mins | L28: =ROUND(calls[[#This Row],[Satisfaction Rating]],0) -> 3 | M28: =IF(calls[[#This Row],[Rating rounded]]>=4,"Happy") -> FALSE | N28: =_xlfn.XLOOKUP(calls[[#This Row],[Customer ID]],customers[Customer ID],customers[Gedner]) -> Female | O28: =_xlfn.XLOOKUP(calls[[#This Row],[Customer ID]],customers[Customer ID],customers[Age]) -> 30 | P28: =_xlfn.XLOOKUP(calls[[#This Row],[Customer ID]],customers[Customer ID],customers[City]) -> Cleveland
B29: Call_7296 | C29: C0012 | D29: 28 | E29: R05 | F29: 44935 | G29: 63 | H29: 4.1 | I29: =IF(MONTH(calls[[#This Row],[Date of Call]])<=6, YEAR(calls[[#This Row],[Date of Call]]), YEAR(calls[[#This Row],[Date of Call]])+1) -> 2023 | J29: =TEXT(calls[[#This Row],[Date of Call]],"DDDD") -> Monday | K29: {=_xlfn.IFS(calls[[#This Row],[Duration]]<=10,"Under 10 mins", calls[[#This Row],[Duration]]<=30, "10 to 30 mins", calls[[#This Row],[Duration]]<=60, "30 to 60 mins", calls[[#This Row],[Duration]]<=120, "1 to 2 hours", TRUE, "More than 2 hours")} -> 10 to 30 mins | L29: =ROUND(calls[[#This Row],[Satisfaction Rating]],0) -> 4 | M29: =IF(calls[[#This Row],[Rating rounded]]>=4,"Happy") -> Happy | N29: =_xlfn.XLOOKUP(calls[[#This Row],[Customer ID]],customers[Customer ID],customers[Gedner]) -> Female | O29: =_xlfn.XLOOKUP(calls[[#This Row],[Customer ID]],customers[Customer ID],customers[Age]) -> 28 | P29: =_xlfn.XLOOKUP(calls[[#This Row],[Customer ID]],customers[Customer ID],customers[City]) -> Cincinnati
B30: Call_7297 | C30: C0002 | D30: 73 | E30: R05 | F30: 44935 | G30: 80 | H30: 4.2 | I30: =IF(MONTH(calls[[#This Row],[Date of Call]])<=6, YEAR(calls[[#This Row],[Date of Call]]), YEAR(calls[[#This Row],[Date of Call]])+1) -> 2023 | J30: =TEXT(calls[[#This Row],[Date of Call]],"DDDD") -> Monday | K30: {=_xlfn.IFS(calls[[#This Row],[Duration]]<=10,"Under 10 mins", calls[[#This Row],[Duration]]<=30, "10 to 30 mins", calls[[#This Row],[Duration]]<=60, "30 to 60 mins", calls[[#This Row],[Duration]]<=120, "1 to 2 hours", TRUE, "More than 2 hours")} -> 1 to 2 hours | L30: =ROUND(calls[[#This Row],[Satisfaction Rating]],0) -> 4 | M30: =IF(calls[[#This Row],[Rating rounded]]>=4,"Happy") -> Happy | N30: =_xlfn.XLOOKUP(calls[[#This Row],[Customer ID]],customers[Customer ID],customers[Gedner]) -> Male | O30: =_xlfn.XLOOKUP(calls[[#This Row],[Customer ID]],customers[Customer ID],customers[Age]) -> 31 | P30: =_xlfn.XLOOKUP(calls[[#This Row],[Customer ID]],customers[Customer ID],customers[City]) -> Cleveland
... B1003: Call_8270 | C1003: C0009 | D1003: 114 | E1003: R01 | F1003: 45291 | G1003: 40 | H1003: 3.9 | I1003: =IF(MONTH(calls[[#This Row],[Date of Call]])<=6, YEAR(calls[[#This Row],[Date of Call]]), YEAR(calls[[#This Row],[Date of Call]])+1) -> 2024 | J1003: =TEXT(calls[[#This Row],[Date of Call]],"DDDD") -> Sunday | K1003: {=_xlfn.IFS(calls[[#This Row],[Duration]]<=10,"Under 10 mins", calls[[#This Row],[Duration]]<=30, "10 to 30 mins", calls[[#This Row],[Duration]]<=60, "30 to 60 mins", calls[[#This Row],[Duration]]<=120, "1 to 2 hours", TRUE, "More than 2 hours")} -> 1 to 2 hours | L1003: =ROUND(calls[[#This Row],[Satisfaction Rating]],0) -> 4 | M1003: =IF(calls[[#This Row],[Rating rounded]]>=4,"Happy") -> Happy | N1003: =_xlfn.XLOOKUP(calls[[#This Row],[Customer ID]],customers[Customer ID],customers[Gedner]) -> Female | O1003: =_xlfn.XLOOKUP(calls[[#This Row],[Customer ID]],customers[Customer ID],customers[Age]) -> 25 | P1003: =_xlfn.XLOOKUP(calls[[#This Row],[Customer ID]],customers[Customer ID],customers[City]) -> Columbus

Sheet Assets
E2: Rep ID | F2: Rep Image
E3: R01 | F3: #VALUE!
E4: R02 | F4: #VALUE!
E5: R03 | F5: #VALUE!
E6: R04 | F6: #VALUE!
E7: R05 | F7: #VALUE!
